<?xml version="1.0"?>
<robot name="bot3" xmlns:xacro="http://www.ros.org.wiki/xacro">

    <xacro:include filename = "$(find descriptions_package)/urdf/bot3_ext_info.xacro"/>
    <xacro:include filename = "$(find descriptions_package)/urdf/bot3_control.xacro"/>


    <link name="base_footprint" />
    <link
        name="base_link">
        <inertial>
            <origin
                xyz="0.018226 -2.0781E-05 -0.13643"
                rpy="0 0 0" />
            <mass
                value="1.0" />
            <inertia
                ixx="0.001014"
                ixy="1.4943E-06"
                ixz="8.6765E-05"
                iyy="0.0027467"
                iyz="2.6408E-07"
                izz="0.0027686" />
        </inertial>
        <visual>
            <origin
                xyz="0 0 0"
                rpy="0 0 0" />
            <geometry>
                <mesh
                    filename="package://descriptions_package/meshes/base_link.STL" />
            </geometry>
            <material
                name="aluminium extrusion 6063">
                <color
                    rgba="0.89804 0.91765 0.92941 1" />
            </material>
        </visual>
        <collision>
            <origin
                xyz="0 0 0"
                rpy="0 0 0" />
            <geometry>
                <mesh
                    filename="package://descriptions_package/meshes/base_link.STL" />
            </geometry>
        </collision>
    </link>
    <joint name="base_link" type="fixed">
        <origin
            xyz="0 0 0.21095"
            rpy="0 0 0" />
        <parent
            link="base_footprint" />
        <child
            link="base_link" />

    </joint>
    <link
        name="front_left_wheel_link">
        <inertial>
            <origin
                xyz="-4.4509E-07 -0.015766 -3.0123E-08"
                rpy="0 0 0" />
            <mass
                value="0.035128" />
            <inertia
                ixx="1.2599E-05"
                ixy="6.3601E-12"
                ixz="-4.9469E-11"
                iyy="1.8665E-05"
                iyz="7.863E-12"
                izz="1.2601E-05" />
        </inertial>
        <visual>
            <origin
                xyz="0 0 0"
                rpy="0 0 0" />
            <geometry>
                <mesh
                    filename="package://descriptions_package/meshes/front_left_wheel_link.STL" />
            </geometry>
            <material
                name="">
                <color
                    rgba="0.29804 0.29804 0.29804 1" />
            </material>
        </visual>
        <collision>
            <origin
                xyz="0 0 0"
                rpy="0 0 0" />
            <geometry>
                <mesh
                    filename="package://descriptions_package/meshes/front_left_wheel_link.STL" />
            </geometry>
        </collision>
    </link>
    <joint
        name="front_left_wheel_joint"
        type="continuous">
        <origin
            xyz="0.20852 0.10925 -0.18091"
            rpy="0 0 0" />
        <parent
            link="base_link" />
        <child
            link="front_left_wheel_link" />
        <axis
            xyz="0 1 0" />
        <limit
            effort="100"
            velocity="10" />
    </joint>
    <link
        name="front_right_wheel_link">
        <inertial>
            <origin
                xyz="2.0522E-07 0.015766 3.9719E-07"
                rpy="0 0 0" />
            <mass
                value="0.035128" />
            <inertia
                ixx="1.26E-05"
                ixy="9.8212E-12"
                ixz="-4.8774E-10"
                iyy="1.8665E-05"
                iyz="2.6737E-12"
                izz="1.26E-05" />
        </inertial>
        <visual>
            <origin
                xyz="0 0 0"
                rpy="0 0 0" />
            <geometry>
                <mesh
                    filename="package://descriptions_package/meshes/front_right_wheel_link.STL" />
            </geometry>
            <material
                name="">
                <color
                    rgba="0.29804 0.29804 0.29804 1" />
            </material>
        </visual>
        <collision>
            <origin
                xyz="0 0 0"
                rpy="0 0 0" />
            <geometry>
                <mesh
                    filename="package://descriptions_package/meshes/front_right_wheel_link.STL" />
            </geometry>
        </collision>
    </link>
    <joint
        name="front_right_wheel_joint"
        type="continuous">
        <origin
            xyz="0.20852 -0.10925 -0.18091"
            rpy="0 0 0" />
        <parent
            link="base_link" />
        <child
            link="front_right_wheel_link" />
        <axis
            xyz="0 1 0" />
        <limit
            effort="100"
            velocity="10" />
    </joint>
    <link
        name="rear_left_wheel_link">
        <inertial>
            <origin
                xyz="-4.4509E-07 -0.015766 -3.0123E-08"
                rpy="0 0 0" />
            <mass
                value="0.035128" />
            <inertia
                ixx="1.2599E-05"
                ixy="6.3601E-12"
                ixz="-4.9469E-11"
                iyy="1.8665E-05"
                iyz="7.863E-12"
                izz="1.2601E-05" />
        </inertial>
        <visual>
            <origin
                xyz="0 0 0"
                rpy="0 0 0" />
            <geometry>
                <mesh
                    filename="package://descriptions_package/meshes/rear_left_wheel_link.STL" />
            </geometry>
            <material
                name="">
                <color
                    rgba="0.29804 0.29804 0.29804 1" />
            </material>
        </visual>
        <collision>
            <origin
                xyz="0 0 0"
                rpy="0 0 0" />
            <geometry>
                <mesh
                    filename="package://descriptions_package/meshes/rear_left_wheel_link.STL" />
            </geometry>
        </collision>
    </link>
    <joint
        name="rear_left_wheel_joint"
        type="continuous">
        <origin
            xyz="-0.17248 0.10925 -0.18091"
            rpy="0 0 0" />
        <parent
            link="base_link" />
        <child
            link="rear_left_wheel_link" />
        <axis
            xyz="0 1 0" />
        <limit
            effort="100"
            velocity="10" />
    </joint>
    <link
        name="rear_right_wheel_link">
        <inertial>
            <origin
                xyz="2.0522E-07 0.015766 3.9719E-07"
                rpy="0 0 0" />
            <mass
                value="0.035128" />
            <inertia
                ixx="1.26E-05"
                ixy="9.8212E-12"
                ixz="-4.8774E-10"
                iyy="1.8665E-05"
                iyz="2.6737E-12"
                izz="1.26E-05" />
        </inertial>
        <visual>
            <origin
                xyz="0 0 0"
                rpy="0 0 0" />
            <geometry>
                <mesh
                    filename="package://descriptions_package/meshes/rear_right_wheel_link.STL" />
            </geometry>
            <material
                name="">
                <color
                    rgba="0.29804 0.29804 0.29804 1" />
            </material>
        </visual>
        <collision>
            <origin
                xyz="0 0 0"
                rpy="0 0 0" />
            <geometry>
                <mesh
                    filename="package://descriptions_package/meshes/rear_right_wheel_link.STL" />
            </geometry>
        </collision>
    </link>
    <joint
        name="rear_right_wheel_joint"
        type="continuous">
        <origin
            xyz="-0.17248 -0.10925 -0.18091"
            rpy="0 0 0" />
        <parent
            link="base_link" />
        <child
            link="rear_right_wheel_link" />
        <axis
            xyz="0 1 0" />
        <limit
            effort="100"
            velocity="10" />
    </joint>
</robot>